Workbook

Sheet Input
A1: Ziele
A4: Kalorienbedarf [kcal]: | B4: 3000
A5: Proteinbedarf [g]: | B5: 200
A6: Anzahl an Mahlzeiten [-]: | B6: 4
A7: Tage [d]: | B7: 4

Sheet Meal 1
A1: Meal 1
A3: Kalorienbedarf [kcal]: | K3: =IF(ISBLANK(B3),Input!B4/Input!B6,B3) -> 750
A4: Proteinbedarf [g]: | K4: =IF(ISBLANK(B4),Input!B5/Input!B7,B4) -> 50
A5: Zutat [Name aus Tabelle] | B5: Menge [g] | C5: Spalte1 | D5: Berechnete Menge [g] | E5: Gesamtmenge [g] | F5: Skal. Gesamtmenge [g] | G5: Kosten [€] | H5: Kalorien [kcal] | I5: Proteine [g] | J5: Kaloriendichte [kcal/g] | K5: Proteindichte [g/g] | L5: Kalorien vorher [kcal] | M5: Proteine vorher [g] | N5: Massenanpassung | O5: Relative Abweichung
A6: Haferflocken | B6: 100 | D6: =IF(ROW()-5=$N$29,Meal1[[#Totals],[Massenanpassung]]*$N$31,Meal1[[#This Row],[Menge '[g']]]*$N$31) -> 72.528061 | E6: =Meal1[[#This Row],[Berechnete Menge '[g']]]*Input!$B$7 -> 290.11224 | F6: =Meal1[[#This Row],[Berechnete Menge '[g']]]*5.43 -> 393.82737 | G6: =IFERROR(VLOOKUP(Meal1[[#This Row],[Zutat '[Name aus Tabelle']]],Tabelle2[],11,FALSE)*Meal1[[#This Row],[Berechnete Menge '[g']]],"") -> 0.11459434 | H6: =IFERROR(Meal1[[#This Row],[Berechnete Menge '[g']]]*Meal1[[#This Row],[Kaloriendichte '[kcal/g']]],"") -> 269.80439 | I6: =IFERROR(Meal1[[#This Row],[Berechnete Menge '[g']]]*Meal1[[#This Row],[Proteindichte '[g/g']]],"") -> 9.7912882 | J6: =IFERROR(VLOOKUP(Meal1[[#This Row],[Zutat '[Name aus Tabelle']]],Tabelle2[],13,FALSE),"") -> 3.72 | K6: =IFERROR(VLOOKUP(Meal1[[#This Row],[Zutat '[Name aus Tabelle']]],Tabelle2[],14,FALSE),"") -> 0.135 | L6: =IFERROR(Meal1[[#This Row],[Kaloriendichte '[kcal/g']]]*Meal1[[#This Row],[Menge '[g']]],0) -> 372 | M6: =IFERROR(Meal1[[#This Row],[Proteindichte '[g/g']]]*Meal1[[#This Row],[Menge '[g']]],0) -> 13.5 | N6: =IFERROR(($N$28*(Meal1[[#Totals],[Kalorien vorher '[kcal']]]-Meal1[[#This Row],[Kalorien vorher '[kcal']]])-(Meal1[[#Totals],[Proteine vorher '[g']]]-Meal1[[#This Row],[Proteine vorher '[g']]]))/(Meal1[[#This Row],[Proteindichte '[g/g']]]-$N$28*Meal1[[#This Row],[Kaloriendichte '[kcal/g']]]),1000000) -> -4.0707965 | O6: =IFERROR(ABS(Meal1[[#This Row],[Massenanpassung]]-Meal1[[#This Row],[Menge '[g']]])/Meal1[[#This Row],[Menge '[g']]],1000000) -> 1.040708
A7: Skyr | B7: 200 | D7: =IF(ROW()-5=$N$29,Meal1[[#Totals],[Massenanpassung]]*$N$31,Meal1[[#This Row],[Menge '[g']]]*$N$31) -> 269.26923 | E7: =Meal1[[#This Row],[Berechnete Menge '[g']]]*Input!$B$7 -> 1077.0769 | F7: =Meal1[[#This Row],[Berechnete Menge '[g']]]*5.43 -> 1462.1319 | G7: =IFERROR(VLOOKUP(Meal1[[#This Row],[Zutat '[Name aus Tabelle']]],Tabelle2[],11,FALSE)*Meal1[[#This Row],[Berechnete Menge '[g']]],"") -> 0.8024223 | H7: =IFERROR(Meal1[[#This Row],[Berechnete Menge '[g']]]*Meal1[[#This Row],[Kaloriendichte '[kcal/g']]],"") -> 166.94692 | I7: =IFERROR(Meal1[[#This Row],[Berechnete Menge '[g']]]*Meal1[[#This Row],[Proteindichte '[g/g']]],"") -> 29.619615 | J7: =IFERROR(VLOOKUP(Meal1[[#This Row],[Zutat '[Name aus Tabelle']]],Tabelle2[],13,FALSE),"") -> 0.62 | K7: =IFERROR(VLOOKUP(Meal1[[#This Row],[Zutat '[Name aus Tabelle']]],Tabelle2[],14,FALSE),"") -> 0.11 | L7: =IFERROR(Meal1[[#This Row],[Kaloriendichte '[kcal/g']]]*Meal1[[#This Row],[Menge '[g']]],0) -> 124 | M7: =IFERROR(Meal1[[#This Row],[Proteindichte '[g/g']]]*Meal1[[#This Row],[Menge '[g']]],0) -> 22 | N7: =IFERROR(($N$28*(Meal1[[#Totals],[Kalorien vorher '[kcal']]]-Meal1[[#This Row],[Kalorien vorher '[kcal']]])-(Meal1[[#Totals],[Proteine vorher '[g']]]-Meal1[[#This Row],[Proteine vorher '[g']]]))/(Meal1[[#This Row],[Proteindichte '[g/g']]]-$N$28*Meal1[[#This Row],[Kaloriendichte '[kcal/g']]]),1000000) -> 371.26214 | O7: =IFERROR(ABS(Meal1[[#This Row],[Massenanpassung]]-Meal1[[#This Row],[Menge '[g']]])/Meal1[[#This Row],[Menge '[g']]],1000000) -> 0.85631068
A8: Apfel | B8: 100 | D8: =IF(ROW()-5=$N$29,Meal1[[#Totals],[Massenanpassung]]*$N$31,Meal1[[#This Row],[Menge '[g']]]*$N$31) -> 72.528061 | E8: =Meal1[[#This Row],[Berechnete Menge '[g']]]*Input!$B$7 -> 290.11224 | F8: =Meal1[[#This Row],[Berechnete Menge '[g']]]*5.43 -> 393.82737 | G8: =IFERROR(VLOOKUP(Meal1[[#This Row],[Zutat '[Name aus Tabelle']]],Tabelle2[],11,FALSE)*Meal1[[#This Row],[Berechnete Menge '[g']]],"") -> 0.10806681 | H8: =IFERROR(Meal1[[#This Row],[Berechnete Menge '[g']]]*Meal1[[#This Row],[Kaloriendichte '[kcal/g']]],"") -> 37.714592 | I8: =IFERROR(Meal1[[#This Row],[Berechnete Menge '[g']]]*Meal1[[#This Row],[Proteindichte '[g/g']]],"") -> 0.21758418 | J8: =IFERROR(VLOOKUP(Meal1[[#This Row],[Zutat '[Name aus Tabelle']]],Tabelle2[],13,FALSE),"") -> 0.52 | K8: =IFERROR(VLOOKUP(Meal1[[#This Row],[Zutat '[Name aus Tabelle']]],Tabelle2[],14,FALSE),"") -> 0.003 | L8: =IFERROR(Meal1[[#This Row],[Kaloriendichte '[kcal/g']]]*Meal1[[#This Row],[Menge '[g']]],0) -> 52 | M8: =IFERROR(Meal1[[#This Row],[Proteindichte '[g/g']]]*Meal1[[#This Row],[Menge '[g']]],0) -> 0.3 | N8: =IFERROR(($N$28*(Meal1[[#Totals],[Kalorien vorher '[kcal']]]-Meal1[[#This Row],[Kalorien vorher '[kcal']]])-(Meal1[[#Totals],[Proteine vorher '[g']]]-Meal1[[#This Row],[Proteine vorher '[g']]]))/(Meal1[[#This Row],[Proteindichte '[g/g']]]-$N$28*Meal1[[#This Row],[Kaloriendichte '[kcal/g']]]),1000000) -> -271.36842 | O8: =IFERROR(ABS(Meal1[[#This Row],[Massenanpassung]]-Meal1[[#This Row],[Menge '[g']]])/Meal1[[#This Row],[Menge '[g']]],1000000) -> 3.7136842
A9: Milch | B9: 200 | D9: =IF(ROW()-5=$N$29,Meal1[[#Totals],[Massenanpassung]]*$N$31,Meal1[[#This Row],[Menge '[g']]]*$N$31) -> 145.05612 | E9: =Meal1[[#This Row],[Berechnete Menge '[g']]]*Input!$B$7 -> 580.22448 | F9: =Meal1[[#This Row],[Berechnete Menge '[g']]]*5.43 -> 787.65474 | G9: =IFERROR(VLOOKUP(Meal1[[#This Row],[Zutat '[Name aus Tabelle']]],Tabelle2[],11,FALSE)*Meal1[[#This Row],[Berechnete Menge '[g']]],"") -> 0.15230893 | H9: =IFERROR(Meal1[[#This Row],[Berechnete Menge '[g']]]*Meal1[[#This Row],[Kaloriendichte '[kcal/g']]],"") -> 92.835918 | I9: =IFERROR(Meal1[[#This Row],[Berechnete Menge '[g']]]*Meal1[[#This Row],[Proteindichte '[g/g']]],"") -> 5.0769642 | J9: =IFERROR(VLOOKUP(Meal1[[#This Row],[Zutat '[Name aus Tabelle']]],Tabelle2[],13,FALSE),"") -> 0.64 | K9: =IFERROR(VLOOKUP(Meal1[[#This Row],[Zutat '[Name aus Tabelle']]],Tabelle2[],14,FALSE),"") -> 0.035 | L9: =IFERROR(Meal1[[#This Row],[Kaloriendichte '[kcal/g']]]*Meal1[[#This Row],[Menge '[g']]],0) -> 128 | M9: =IFERROR(Meal1[[#This Row],[Proteindichte '[g/g']]]*Meal1[[#This Row],[Menge '[g']]],0) -> 7 | N9: =IFERROR(($N$28*(Meal1[[#Totals],[Kalorien vorher '[kcal']]]-Meal1[[#This Row],[Kalorien vorher '[kcal']]])-(Meal1[[#Totals],[Proteine vorher '[g']]]-Meal1[[#This Row],[Proteine vorher '[g']]]))/(Meal1[[#This Row],[Proteindichte '[g/g']]]-$N$28*Meal1[[#This Row],[Kaloriendichte '[kcal/g']]]),1000000) -> -1333.913 | O9: =IFERROR(ABS(Meal1[[#This Row],[Massenanpassung]]-Meal1[[#This Row],[Menge '[g']]])/Meal1[[#This Row],[Menge '[g']]],1000000) -> 7.6695652
A10: Mandeln | B10: 30 | D10: =IF(ROW()-5=$N$29,Meal1[[#Totals],[Massenanpassung]]*$N$31,Meal1[[#This Row],[Menge '[g']]]*$N$31) -> 21.758418 | E10: =Meal1[[#This Row],[Berechnete Menge '[g']]]*Input!$B$7 -> 87.033673 | F10: =Meal1[[#This Row],[Berechnete Menge '[g']]]*5.43 -> 118.14821 | G10: =IFERROR(VLOOKUP(Meal1[[#This Row],[Zutat '[Name aus Tabelle']]],Tabelle2[],11,FALSE)*Meal1[[#This Row],[Berechnete Menge '[g']]],"") -> 0.24913389 | H10: =IFERROR(Meal1[[#This Row],[Berechnete Menge '[g']]]*Meal1[[#This Row],[Kaloriendichte '[kcal/g']]],"") -> 134.68461 | I10: =IFERROR(Meal1[[#This Row],[Berechnete Menge '[g']]]*Meal1[[#This Row],[Proteindichte '[g/g']]],"") -> 5.2220204 | J10: =IFERROR(VLOOKUP(Meal1[[#This Row],[Zutat '[Name aus Tabelle']]],Tabelle2[],13,FALSE),"") -> 6.19 | K10: =IFERROR(VLOOKUP(Meal1[[#This Row],[Zutat '[Name aus Tabelle']]],Tabelle2[],14,FALSE),"") -> 0.24 | L10: =IFERROR(Meal1[[#This Row],[Kaloriendichte '[kcal/g']]]*Meal1[[#This Row],[Menge '[g']]],0) -> 185.7 | M10: =IFERROR(Meal1[[#This Row],[Proteindichte '[g/g']]]*Meal1[[#This Row],[Menge '[g']]],0) -> 7.2 | N10: =IFERROR(($N$28*(Meal1[[#Totals],[Kalorien vorher '[kcal']]]-Meal1[[#This Row],[Kalorien vorher '[kcal']]])-(Meal1[[#Totals],[Proteine vorher '[g']]]-Meal1[[#This Row],[Proteine vorher '[g']]]))/(Meal1[[#This Row],[Proteindichte '[g/g']]]-$N$28*Meal1[[#This Row],[Kaloriendichte '[kcal/g']]]),1000000) -> -38.108108 | O10: =IFERROR(ABS(Meal1[[#This Row],[Massenanpassung]]-Meal1[[#This Row],[Menge '[g']]])/Meal1[[#This Row],[Menge '[g']]],1000000) -> 2.2702703
A11: Honig | B11: 20 | D11: =IF(ROW()-5=$N$29,Meal1[[#Totals],[Massenanpassung]]*$N$31,Meal1[[#This Row],[Menge '[g']]]*$N$31) -> 14.505612 | E11: =Meal1[[#This Row],[Berechnete Menge '[g']]]*Input!$B$7 -> 58.022448 | F11: =Meal1[[#This Row],[Berechnete Menge '[g']]]*5.43 -> 78.765474 | G11: =IFERROR(VLOOKUP(Meal1[[#This Row],[Zutat '[Name aus Tabelle']]],Tabelle2[],11,FALSE)*Meal1[[#This Row],[Berechnete Menge '[g']]],"") -> 0.029011224 | H11: =IFERROR(Meal1[[#This Row],[Berechnete Menge '[g']]]*Meal1[[#This Row],[Kaloriendichte '[kcal/g']]],"") -> 48.013576 | I11: =IFERROR(Meal1[[#This Row],[Berechnete Menge '[g']]]*Meal1[[#This Row],[Proteindichte '[g/g']]],"") -> 0.072528061 | J11: =IFERROR(VLOOKUP(Meal1[[#This Row],[Zutat '[Name aus Tabelle']]],Tabelle2[],13,FALSE),"") -> 3.31 | K11: =IFERROR(VLOOKUP(Meal1[[#This Row],[Zutat '[Name aus Tabelle']]],Tabelle2[],14,FALSE),"") -> 0.005 | L11: =IFERROR(Meal1[[#This Row],[Kaloriendichte '[kcal/g']]]*Meal1[[#This Row],[Menge '[g']]],0) -> 66.2 | M11: =IFERROR(Meal1[[#This Row],[Proteindichte '[g/g']]]*Meal1[[#This Row],[Menge '[g']]],0) -> 0.1 | N11: =IFERROR(($N$28*(Meal1[[#Totals],[Kalorien vorher '[kcal']]]-Meal1[[#This Row],[Kalorien vorher '[kcal']]])-(Meal1[[#Totals],[Proteine vorher '[g']]]-Meal1[[#This Row],[Proteine vorher '[g']]]))/(Meal1[[#This Row],[Proteindichte '[g/g']]]-$N$28*Meal1[[#This Row],[Kaloriendichte '[kcal/g']]]),1000000) -> -34.528594 | O11: =IFERROR(ABS(Meal1[[#This Row],[Massenanpassung]]-Meal1[[#This Row],[Menge '[g']]])/Meal1[[#This Row],[Menge '[g']]],1000000) -> 2.7264297
D12: =IF(ROW()-5=$N$29,Meal1[[#Totals],[Massenanpassung]]*$N$31,Meal1[[#This Row],[Menge '[g']]]*$N$31) -> 0 | E12: =Meal1[[#This Row],[Berechnete Menge '[g']]]*Input!$B$7 -> 0 | F12: =Meal1[[#This Row],[Berechnete Menge '[g']]]*5.43 -> 0 | G12: =IFERROR(VLOOKUP(Meal1[[#This Row],[Zutat '[Name aus Tabelle']]],Tabelle2[],11,FALSE)*Meal1[[#This Row],[Berechnete Menge '[g']]],"") | H12: =IFERROR(Meal1[[#This Row],[Berechnete Menge '[g']]]*Meal1[[#This Row],[Kaloriendichte '[kcal/g']]],"") | I12: =IFERROR(Meal1[[#This Row],[Berechnete Menge '[g']]]*Meal1[[#This Row],[Proteindichte '[g/g']]],"") | J12: =IFERROR(VLOOKUP(Meal1[[#This Row],[Zutat '[Name aus Tabelle']]],Tabelle2[],13,FALSE),"") | K12: =IFERROR(VLOOKUP(Meal1[[#This Row],[Zutat '[Name aus Tabelle']]],Tabelle2[],14,FALSE),"") | L12: =IFERROR(Meal1[[#This Row],[Kaloriendichte '[kcal/g']]]*Meal1[[#This Row],[Menge '[g']]],0) -> 0 | M12: =IFERROR(Meal1[[#This Row],[Proteindichte '[g/g']]]*Meal1[[#This Row],[Menge '[g']]],0) -> 0 | N12: =IFERROR(($N$28*(Meal1[[#Totals],[Kalorien vorher '[kcal']]]-Meal1[[#This Row],[Kalorien vorher '[kcal']]])-(Meal1[[#Totals],[Proteine vorher '[g']]]-Meal1[[#This Row],[Proteine vorher '[g']]]))/(Meal1[[#This Row],[Proteindichte '[g/g']]]-$N$28*Meal1[[#This Row],[Kaloriendichte '[kcal/g']]]),1000000) -> 1000000 | O12: =IFERROR(ABS(Meal1[[#This Row],[Massenanpassung]]-Meal1[[#This Row],[Menge '[g']]])/Meal1[[#This Row],[Menge '[g']]],1000000) -> 1000000
D13: =IF(ROW()-5=$N$29,Meal1[[#Totals],[Massenanpassung]]*$N$31,Meal1[[#This Row],[Menge '[g']]]*$N$31) -> 0 | E13: =Meal1[[#This Row],[Berechnete Menge '[g']]]*Input!$B$7 -> 0 | F13: =Meal1[[#This Row],[Berechnete Menge '[g']]]*5.43 -> 0 | G13: =IFERROR(VLOOKUP(Meal1[[#This Row],[Zutat '[Name aus Tabelle']]],Tabelle2[],11,FALSE)*Meal1[[#This Row],[Berechnete Menge '[g']]],"") | H13: =IFERROR(Meal1[[#This Row],[Berechnete Menge '[g']]]*Meal1[[#This Row],[Kaloriendichte '[kcal/g']]],"") | I13: =IFERROR(Meal1[[#This Row],[Berechnete Menge '[g']]]*Meal1[[#This Row],[Proteindichte '[g/g']]],"") | J13: =IFERROR(VLOOKUP(Meal1[[#This Row],[Zutat '[Name aus Tabelle']]],Tabelle2[],13,FALSE),"") | K13: =IFERROR(VLOOKUP(Meal1[[#This Row],[Zutat '[Name aus Tabelle']]],Tabelle2[],14,FALSE),"") | L13: =IFERROR(Meal1[[#This Row],[Kaloriendichte '[kcal/g']]]*Meal1[[#This Row],[Menge '[g']]],0) -> 0 | M13: =IFERROR(Meal1[[#This Row],[Proteindichte '[g/g']]]*Meal1[[#This Row],[Menge '[g']]],0) -> 0 | N13: =IFERROR(($N$28*(Meal1[[#Totals],[Kalorien vorher '[kcal']]]-Meal1[[#This Row],[Kalorien vorher '[kcal']]])-(Meal1[[#Totals],[Proteine vorher '[g']]]-Meal1[[#This Row],[Proteine vorher '[g']]]))/(Meal1[[#This Row],[Proteindichte '[g/g']]]-$N$28*Meal1[[#This Row],[Kaloriendichte '[kcal/g']]]),1000000) -> 1000000 | O13: =IFERROR(ABS(Meal1[[#This Row],[Massenanpassung]]-Meal1[[#This Row],[Menge '[g']]])/Meal1[[#This Row],[Menge '[g']]],1000000) -> 1000000
D14: =IF(ROW()-5=$N$29,Meal1[[#Totals],[Massenanpassung]]*$N$31,Meal1[[#This Row],[Menge '[g']]]*$N$31) -> 0 | E14: =Meal1[[#This Row],[Berechnete Menge '[g']]]*Input!$B$7 -> 0 | F14: =Meal1[[#This Row],[Berechnete Menge '[g']]]*5.43 -> 0 | G14: =IFERROR(VLOOKUP(Meal1[[#This Row],[Zutat '[Name aus Tabelle']]],Tabelle2[],11,FALSE)*Meal1[[#This Row],[Berechnete Menge '[g']]],"") | H14: =IFERROR(Meal1[[#This Row],[Berechnete Menge '[g']]]*Meal1[[#This Row],[Kaloriendichte '[kcal/g']]],"") | I14: =IFERROR(Meal1[[#This Row],[Berechnete Menge '[g']]]*Meal1[[#This Row],[Proteindichte '[g/g']]],"") | J14: =IFERROR(VLOOKUP(Meal1[[#This Row],[Zutat '[Name aus Tabelle']]],Tabelle2[],13,FALSE),"") | K14: =IFERROR(VLOOKUP(Meal1[[#This Row],[Zutat '[Name aus Tabelle']]],Tabelle2[],14,FALSE),"") | L14: =IFERROR(Meal1[[#This Row],[Kaloriendichte '[kcal/g']]]*Meal1[[#This Row],[Menge '[g']]],0) -> 0 | M14: =IFERROR(Meal1[[#This Row],[Proteindichte '[g/g']]]*Meal1[[#This Row],[Menge '[g']]],0) -> 0 | N14: =IFERROR(($N$28*(Meal1[[#Totals],[Kalorien vorher '[kcal']]]-Meal1[[#This Row],[Kalorien vorher '[kcal']]])-(Meal1[[#Totals],[Proteine vorher '[g']]]-Meal1[[#This Row],[Proteine vorher '[g']]]))/(Meal1[[#This Row],[Proteindichte '[g/g']]]-$N$28*Meal1[[#This Row],[Kaloriendichte '[kcal/g']]]),1000000) -> 1000000 | O14: =IFERROR(ABS(Meal1[[#This Row],[Massenanpassung]]-Meal1[[#This Row],[Menge '[g']]])/Meal1[[#This Row],[Menge '[g']]],1000000) -> 1000000
D15: =IF(ROW()-5=$N$29,Meal1[[#Totals],[Massenanpassung]]*$N$31,Meal1[[#This Row],[Menge '[g']]]*$N$31) -> 0 | E15: =Meal1[[#This Row],[Berechnete Menge '[g']]]*Input!$B$7 -> 0 | F15: =Meal1[[#This Row],[Berechnete Menge '[g']]]*5.43 -> 0 | G15: =IFERROR(VLOOKUP(Meal1[[#This Row],[Zutat '[Name aus Tabelle']]],Tabelle2[],11,FALSE)*Meal1[[#This Row],[Berechnete Menge '[g']]],"") | H15: =IFERROR(Meal1[[#This Row],[Berechnete Menge '[g']]]*Meal1[[#This Row],[Kaloriendichte '[kcal/g']]],"") | I15: =IFERROR(Meal1[[#This Row],[Berechnete Menge '[g']]]*Meal1[[#This Row],[Proteindichte '[g/g']]],"") | J15: =IFERROR(VLOOKUP(Meal1[[#This Row],[Zutat '[Name aus Tabelle']]],Tabelle2[],13,FALSE),"") | K15: =IFERROR(VLOOKUP(Meal1[[#This Row],[Zutat '[Name aus Tabelle']]],Tabelle2[],14,FALSE),"") | L15: =IFERROR(Meal1[[#This Row],[Kaloriendichte '[kcal/g']]]*Meal1[[#This Row],[Menge '[g']]],0) -> 0 | M15: =IFERROR(Meal1[[#This Row],[Proteindichte '[g/g']]]*Meal1[[#This Row],[Menge '[g']]],0) -> 0 | N15: =IFERROR(($N$28*(Meal1[[#Totals],[Kalorien vorher '[kcal']]]-Meal1[[#This Row],[Kalorien vorher '[kcal']]])-(Meal1[[#Totals],[Proteine vorher '[g']]]-Meal1[[#This Row],[Proteine vorher '[g']]]))/(Meal1[[#This Row],[Proteindichte '[g/g']]]-$N$28*Meal1[[#This Row],[Kaloriendichte '[kcal/g']]]),1000000) -> 1000000 | O15: =IFERROR(ABS(Meal1[[#This Row],[Massenanpassung]]-Meal1[[#This Row],[Menge '[g']]])/Meal1[[#This Row],[Menge '[g']]],1000000) -> 1000000
D16: =IF(ROW()-5=$N$29,Meal1[[#Totals],[Massenanpassung]]*$N$31,Meal1[[#This Row],[Menge '[g']]]*$N$31) -> 0 | E16: =Meal1[[#This Row],[Berechnete Menge '[g']]]*Input!$B$7 -> 0 | F16: =Meal1[[#This Row],[Berechnete Menge '[g']]]*5.43 -> 0 | G16: =IFERROR(VLOOKUP(Meal1[[#This Row],[Zutat '[Name aus Tabelle']]],Tabelle2[],11,FALSE)*Meal1[[#This Row],[Berechnete Menge '[g']]],"") | H16: =IFERROR(Meal1[[#This Row],[Berechnete Menge '[g']]]*Meal1[[#This Row],[Kaloriendichte '[kcal/g']]],"") | I16: =IFERROR(Meal1[[#This Row],[Berechnete Menge '[g']]]*Meal1[[#This Row],[Proteindichte '[g/g']]],"") | J16: =IFERROR(VLOOKUP(Meal1[[#This Row],[Zutat '[Name aus Tabelle']]],Tabelle2[],13,FALSE),"") | K16: =IFERROR(VLOOKUP(Meal1[[#This Row],[Zutat '[Name aus Tabelle']]],Tabelle2[],14,FALSE),"") | L16: =IFERROR(Meal1[[#This Row],[Kaloriendichte '[kcal/g']]]*Meal1[[#This Row],[Menge '[g']]],0) -> 0 | M16: =IFERROR(Meal1[[#This Row],[Proteindichte '[g/g']]]*Meal1[[#This Row],[Menge '[g']]],0) -> 0 | N16: =IFERROR(($N$28*(Meal1[[#Totals],[Kalorien vorher '[kcal']]]-Meal1[[#This Row],[Kalorien vorher '[kcal']]])-(Meal1[[#Totals],[Proteine vorher '[g']]]-Meal1[[#This Row],[Proteine vorher '[g']]]))/(Meal1[[#This Row],[Proteindichte '[g/g']]]-$N$28*Meal1[[#This Row],[Kaloriendichte '[kcal/g']]]),1000000) -> 1000000 | O16: =IFERROR(ABS(Meal1[[#This Row],[Massenanpassung]]-Meal1[[#This Row],[Menge '[g']]])/Meal1[[#This Row],[Menge '[g']]],1000000) -> 1000000
D17: =IF(ROW()-5=$N$29,Meal1[[#Totals],[Massenanpassung]]*$N$31,Meal1[[#This Row],[Menge '[g']]]*$N$31) -> 0 | E17: =Meal1[[#This Row],[Berechnete Menge '[g']]]*Input!$B$7 -> 0 | F17: =Meal1[[#This Row],[Berechnete Menge '[g']]]*5.43 -> 0 | G17: =IFERROR(VLOOKUP(Meal1[[#This Row],[Zutat '[Name aus Tabelle']]],Tabelle2[],11,FALSE)*Meal1[[#This Row],[Berechnete Menge '[g']]],"") | H17: =IFERROR(Meal1[[#This Row],[Berechnete Menge '[g']]]*Meal1[[#This Row],[Kaloriendichte '[kcal/g']]],"") | I17: =IFERROR(Meal1[[#This Row],[Berechnete Menge '[g']]]*Meal1[[#This Row],[Proteindichte '[g/g']]],"") | J17: =IFERROR(VLOOKUP(Meal1[[#This Row],[Zutat '[Name aus Tabelle']]],Tabelle2[],13,FALSE),"") | K17: =IFERROR(VLOOKUP(Meal1[[#This Row],[Zutat '[Name aus Tabelle']]],Tabelle2[],14,FALSE),"") | L17: =IFERROR(Meal1[[#This Row],[Kaloriendichte '[kcal/g']]]*Meal1[[#This Row],[Menge '[g']]],0) -> 0 | M17: =IFERROR(Meal1[[#This Row],[Proteindichte '[g/g']]]*Meal1[[#This Row],[Menge '[g']]],0) -> 0 | N17: =IFERROR(($N$28*(Meal1[[#Totals],[Kalorien vorher '[kcal']]]-Meal1[[#This Row],[Kalorien vorher '[kcal']]])-(Meal1[[#Totals],[Proteine vorher '[g']]]-Meal1[[#This Row],[Proteine vorher '[g']]]))/(Meal1[[#This Row],[Proteindichte '[g/g']]]-$N$28*Meal1[[#This Row],[Kaloriendichte '[kcal/g']]]),1000000) -> 1000000 | O17: =IFERROR(ABS(Meal1[[#This Row],[Massenanpassung]]-Meal1[[#This Row],[Menge '[g']]])/Meal1[[#This Row],[Menge '[g']]],1000000) -> 1000000
D18: =IF(ROW()-5=$N$29,Meal1[[#Totals],[Massenanpassung]]*$N$31,Meal1[[#This Row],[Menge '[g']]]*$N$31) -> 0 | E18: =Meal1[[#This Row],[Berechnete Menge '[g']]]*Input!$B$7 -> 0 | F18: =Meal1[[#This Row],[Berechnete Menge '[g']]]*5.43 -> 0 | G18: =IFERROR(VLOOKUP(Meal1[[#This Row],[Zutat '[Name aus Tabelle']]],Tabelle2[],11,FALSE)*Meal1[[#This Row],[Berechnete Menge '[g']]],"") | H18: =IFERROR(Meal1[[#This Row],[Berechnete Menge '[g']]]*Meal1[[#This Row],[Kaloriendichte '[kcal/g']]],"") | I18: =IFERROR(Meal1[[#This Row],[Berechnete Menge '[g']]]*Meal1[[#This Row],[Proteindichte '[g/g']]],"") | J18: =IFERROR(VLOOKUP(Meal1[[#This Row],[Zutat '[Name aus Tabelle']]],Tabelle2[],13,FALSE),"") | K18: =IFERROR(VLOOKUP(Meal1[[#This Row],[Zutat '[Name aus Tabelle']]],Tabelle2[],14,FALSE),"") | L18: =IFERROR(Meal1[[#This Row],[Kaloriendichte '[kcal/g']]]*Meal1[[#This Row],[Menge '[g']]],0) -> 0 | M18: =IFERROR(Meal1[[#This Row],[Proteindichte '[g/g']]]*Meal1[[#This Row],[Menge '[g']]],0) -> 0 | N18: =IFERROR(($N$28*(Meal1[[#Totals],[Kalorien vorher '[kcal']]]-Meal1[[#This Row],[Kalorien vorher '[kcal']]])-(Meal1[[#Totals],[Proteine vorher '[g']]]-Meal1[[#This Row],[Proteine vorher '[g']]]))/(Meal1[[#This Row],[Proteindichte '[g/g']]]-$N$28*Meal1[[#This Row],[Kaloriendichte '[kcal/g']]]),1000000) -> 1000000 | O18: =IFERROR(ABS(Meal1[[#This Row],[Massenanpassung]]-Meal1[[#This Row],[Menge '[g']]])/Meal1[[#This Row],[Menge '[g']]],1000000) -> 1000000
D19: =IF(ROW()-5=$N$29,Meal1[[#Totals],[Massenanpassung]]*$N$31,Meal1[[#This Row],[Menge '[g']]]*$N$31) -> 0 | E19: =Meal1[[#This Row],[Berechnete Menge '[g']]]*Input!$B$7 -> 0 | F19: =Meal1[[#This Row],[Berechnete Menge '[g']]]*5.43 -> 0 | G19: =IFERROR(VLOOKUP(Meal1[[#This Row],[Zutat '[Name aus Tabelle']]],Tabelle2[],11,FALSE)*Meal1[[#This Row],[Berechnete Menge '[g']]],"") | H19: =IFERROR(Meal1[[#This Row],[Berechnete Menge '[g']]]*Meal1[[#This Row],[Kaloriendichte '[kcal/g']]],"") | I19: =IFERROR(Meal1[[#This Row],[Berechnete Menge '[g']]]*Meal1[[#This Row],[Proteindichte '[g/g']]],"") | J19: =IFERROR(VLOOKUP(Meal1[[#This Row],[Zutat '[Name aus Tabelle']]],Tabelle2[],13,FALSE),"") | K19: =IFERROR(VLOOKUP(Meal1[[#This Row],[Zutat '[Name aus Tabelle']]],Tabelle2[],14,FALSE),"") | L19: =IFERROR(Meal1[[#This Row],[Kaloriendichte '[kcal/g']]]*Meal1[[#This Row],[Menge '[g']]],0) -> 0 | M19: =IFERROR(Meal1[[#This Row],[Proteindichte '[g/g']]]*Meal1[[#This Row],[Menge '[g']]],0) -> 0 | N19: =IFERROR(($N$28*(Meal1[[#Totals],[Kalorien vorher '[kcal']]]-Meal1[[#This Row],[Kalorien vorher '[kcal']]])-(Meal1[[#Totals],[Proteine vorher '[g']]]-Meal1[[#This Row],[Proteine vorher '[g']]]))/(Meal1[[#This Row],[Proteindichte '[g/g']]]-$N$28*Meal1[[#This Row],[Kaloriendichte '[kcal/g']]]),1000000) -> 1000000 | O19: =IFERROR(ABS(Meal1[[#This Row],[Massenanpassung]]-Meal1[[#This Row],[Menge '[g']]])/Meal1[[#This Row],[Menge '[g']]],1000000) -> 1000000
D20: =IF(ROW()-5=$N$29,Meal1[[#Totals],[Massenanpassung]]*$N$31,Meal1[[#This Row],[Menge '[g']]]*$N$31) -> 0 | E20: =Meal1[[#This Row],[Berechnete Menge '[g']]]*Input!$B$7 -> 0 | F20: =Meal1[[#This Row],[Berechnete Menge '[g']]]*5.43 -> 0 | G20: =IFERROR(VLOOKUP(Meal1[[#This Row],[Zutat '[Name aus Tabelle']]],Tabelle2[],11,FALSE)*Meal1[[#This Row],[Berechnete Menge '[g']]],"") | H20: =IFERROR(Meal1[[#This Row],[Berechnete Menge '[g']]]*Meal1[[#This Row],[Kaloriendichte '[kcal/g']]],"") | I20: =IFERROR(Meal1[[#This Row],[Berechnete Menge '[g']]]*Meal1[[#This Row],[Proteindichte '[g/g']]],"") | J20: =IFERROR(VLOOKUP(Meal1[[#This Row],[Zutat '[Name aus Tabelle']]],Tabelle2[],13,FALSE),"") | K20: =IFERROR(VLOOKUP(Meal1[[#This Row],[Zutat '[Name aus Tabelle']]],Tabelle2[],14,FALSE),"") | L20: =IFERROR(Meal1[[#This Row],[Kaloriendichte '[kcal/g']]]*Meal1[[#This Row],[Menge '[g']]],0) -> 0 | M20: =IFERROR(Meal1[[#This Row],[Proteindichte '[g/g']]]*Meal1[[#This Row],[Menge '[g']]],0) -> 0 | N20: =IFERROR(($N$28*(Meal1[[#Totals],[Kalorien vorher '[kcal']]]-Meal1[[#This Row],[Kalorien vorher '[kcal']]])-(Meal1[[#Totals],[Proteine vorher '[g']]]-Meal1[[#This Row],[Proteine vorher '[g']]]))/(Meal1[[#This Row],[Proteindichte '[g/g']]]-$N$28*Meal1[[#This Row],[Kaloriendichte '[kcal/g']]]),1000000) -> 1000000 | O20: =IFERROR(ABS(Meal1[[#This Row],[Massenanpassung]]-Meal1[[#This Row],[Menge '[g']]])/Meal1[[#This Row],[Menge '[g']]],1000000) -> 1000000
D21: =IF(ROW()-5=$N$29,Meal1[[#Totals],[Massenanpassung]]*$N$31,Meal1[[#This Row],[Menge '[g']]]*$N$31) -> 0 | E21: =Meal1[[#This Row],[Berechnete Menge '[g']]]*Input!$B$7 -> 0 | F21: =Meal1[[#This Row],[Berechnete Menge '[g']]]*5.43 -> 0 | G21: =IFERROR(VLOOKUP(Meal1[[#This Row],[Zutat '[Name aus Tabelle']]],Tabelle2[],11,FALSE)*Meal1[[#This Row],[Berechnete Menge '[g']]],"") | H21: =IFERROR(Meal1[[#This Row],[Berechnete Menge '[g']]]*Meal1[[#This Row],[Kaloriendichte '[kcal/g']]],"") | I21: =IFERROR(Meal1[[#This Row],[Berechnete Menge '[g']]]*Meal1[[#This Row],[Proteindichte '[g/g']]],"") | J21: =IFERROR(VLOOKUP(Meal1[[#This Row],[Zutat '[Name aus Tabelle']]],Tabelle2[],13,FALSE),"") | K21: =IFERROR(VLOOKUP(Meal1[[#This Row],[Zutat '[Name aus Tabelle']]],Tabelle2[],14,FALSE),"") | L21: =IFERROR(Meal1[[#This Row],[Kaloriendichte '[kcal/g']]]*Meal1[[#This Row],[Menge '[g']]],0) -> 0 | M21: =IFERROR(Meal1[[#This Row],[Proteindichte '[g/g']]]*Meal1[[#This Row],[Menge '[g']]],0) -> 0 | N21: =IFERROR(($N$28*(Meal1[[#Totals],[Kalorien vorher '[kcal']]]-Meal1[[#This Row],[Kalorien vorher '[kcal']]])-(Meal1[[#Totals],[Proteine vorher '[g']]]-Meal1[[#This Row],[Proteine vorher '[g']]]))/(Meal1[[#This Row],[Proteindichte '[g/g']]]-$N$28*Meal1[[#This Row],[Kaloriendichte '[kcal/g']]]),1000000) -> 1000000 | O21: =IFERROR(ABS(Meal1[[#This Row],[Massenanpassung]]-Meal1[[#This Row],[Menge '[g']]])/Meal1[[#This Row],[Menge '[g']]],1000000) -> 1000000
D22: =IF(ROW()-5=$N$29,Meal1[[#Totals],[Massenanpassung]]*$N$31,Meal1[[#This Row],[Menge '[g']]]*$N$31) -> 0 | E22: =Meal1[[#This Row],[Berechnete Menge '[g']]]*Input!$B$7 -> 0 | F22: =Meal1[[#This Row],[Berechnete Menge '[g']]]*5.43 -> 0 | G22: =IFERROR(VLOOKUP(Meal1[[#This Row],[Zutat '[Name aus Tabelle']]],Tabelle2[],11,FALSE)*Meal1[[#This Row],[Berechnete Menge '[g']]],"") | H22: =IFERROR(Meal1[[#This Row],[Berechnete Menge '[g']]]*Meal1[[#This Row],[Kaloriendichte '[kcal/g']]],"") | I22: =IFERROR(Meal1[[#This Row],[Berechnete Menge '[g']]]*Meal1[[#This Row],[Proteindichte '[g/g']]],"") | J22: =IFERROR(VLOOKUP(Meal1[[#This Row],[Zutat '[Name aus Tabelle']]],Tabelle2[],13,FALSE),"") | K22: =IFERROR(VLOOKUP(Meal1[[#This Row],[Zutat '[Name aus Tabelle']]],Tabelle2[],14,FALSE),"") | L22: =IFERROR(Meal1[[#This Row],[Kaloriendichte '[kcal/g']]]*Meal1[[#This Row],[Menge '[g']]],0) -> 0 | M22: =IFERROR(Meal1[[#This Row],[Proteindichte '[g/g']]]*Meal1[[#This Row],[Menge '[g']]],0) -> 0 | N22: =IFERROR(($N$28*(Meal1[[#Totals],[Kalorien vorher '[kcal']]]-Meal1[[#This Row],[Kalorien vorher '[kcal']]])-(Meal1[[#Totals],[Proteine vorher '[g']]]-Meal1[[#This Row],[Proteine vorher '[g']]]))/(Meal1[[#This Row],[Proteindichte '[g/g']]]-$N$28*Meal1[[#This Row],[Kaloriendichte '[kcal/g']]]),1000000) -> 1000000 | O22: =IFERROR(ABS(Meal1[[#This Row],[Massenanpassung]]-Meal1[[#This Row],[Menge '[g']]])/Meal1[[#This Row],[Menge '[g']]],1000000) -> 1000000
D23: =IF(ROW()-5=$N$29,Meal1[[#Totals],[Massenanpassung]]*$N$31,Meal1[[#This Row],[Menge '[g']]]*$N$31) -> 0 | E23: =Meal1[[#This Row],[Berechnete Menge '[g']]]*Input!$B$7 -> 0 | F23: =Meal1[[#This Row],[Berechnete Menge '[g']]]*5.43 -> 0 | G23: =IFERROR(VLOOKUP(Meal1[[#This Row],[Zutat '[Name aus Tabelle']]],Tabelle2[],11,FALSE)*Meal1[[#This Row],[Berechnete Menge '[g']]],"") | H23: =IFERROR(Meal1[[#This Row],[Berechnete Menge '[g']]]*Meal1[[#This Row],[Kaloriendichte '[kcal/g']]],"") | I23: =IFERROR(Meal1[[#This Row],[Berechnete Menge '[g']]]*Meal1[[#This Row],[Proteindichte '[g/g']]],"") | J23: =IFERROR(VLOOKUP(Meal1[[#This Row],[Zutat '[Name aus Tabelle']]],Tabelle2[],13,FALSE),"") | K23: =IFERROR(VLOOKUP(Meal1[[#This Row],[Zutat '[Name aus Tabelle']]],Tabelle2[],14,FALSE),"") | L23: =IFERROR(Meal1[[#This Row],[Kaloriendichte '[kcal/g']]]*Meal1[[#This Row],[Menge '[g']]],0) -> 0 | M23: =IFERROR(Meal1[[#This Row],[Proteindichte '[g/g']]]*Meal1[[#This Row],[Menge '[g']]],0) -> 0 | N23: =IFERROR(($N$28*(Meal1[[#Totals],[Kalorien vorher '[kcal']]]-Meal1[[#This Row],[Kalorien vorher '[kcal']]])-(Meal1[[#Totals],[Proteine vorher '[g']]]-Meal1[[#This Row],[Proteine vorher '[g']]]))/(Meal1[[#This Row],[Proteindichte '[g/g']]]-$N$28*Meal1[[#This Row],[Kaloriendichte '[kcal/g']]]),1000000) -> 1000000 | O23: =IFERROR(ABS(Meal1[[#This Row],[Massenanpassung]]-Meal1[[#This Row],[Menge '[g']]])/Meal1[[#This Row],[Menge '[g']]],1000000) -> 1000000
... D26: =IF(ROW()-5=$N$29,Meal1[[#Totals],[Massenanpassung]]*$N$31,Meal1[[#This Row],[Menge '[g']]]*$N$31) -> 0 | E26: =Meal1[[#This Row],[Berechnete Menge '[g']]]*Input!$B$7 -> 0 | F26: =Meal1[[#This Row],[Berechnete Menge '[g']]]*5.43 -> 0 | G26: =IFERROR(VLOOKUP(Meal1[[#This Row],[Zutat '[Name aus Tabelle']]],Tabelle2[],11,FALSE)*Meal1[[#This Row],[Berechnete Menge '[g']]],"") | H26: =IFERROR(Meal1[[#This Row],[Berechnete Menge '[g']]]*Meal1[[#This Row],[Kaloriendichte '[kcal/g']]],"") | I26: =IFERROR(Meal1[[#This Row],[Berechnete Menge '[g']]]*Meal1[[#This Row],[Proteindichte '[g/g']]],"") | J26: =IFERROR(VLOOKUP(Meal1[[#This Row],[Zutat '[Name aus Tabelle']]],Tabelle2[],13,FALSE),"") | K26: =IFERROR(VLOOKUP(Meal1[[#This Row],[Zutat '[Name aus Tabelle']]],Tabelle2[],14,FALSE),"") | L26: =IFERROR(Meal1[[#This Row],[Kaloriendichte '[kcal/g']]]*Meal1[[#This Row],[Menge '[g']]],0) -> 0 | M26: =IFERROR(Meal1[[#This Row],[Proteindichte '[g/g']]]*Meal1[[#This Row],[Menge '[g']]],0) -> 0 | N26: =IFERROR(($N$28*(Meal1[[#Totals],[Kalorien vorher '[kcal']]]-Meal1[[#This Row],[Kalorien vorher '[kcal']]])-(Meal1[[#Totals],[Proteine vorher '[g']]]-Meal1[[#This Row],[Proteine vorher '[g']]]))/(Meal1[[#This Row],[Proteindichte '[g/g']]]-$N$28*Meal1[[#This Row],[Kaloriendichte '[kcal/g']]]),1000000) -> 1000000 | O26: =IFERROR(ABS(Meal1[[#This Row],[Massenanpassung]]-Meal1[[#This Row],[Menge '[g']]])/Meal1[[#This Row],[Menge '[g']]],1000000) -> 1000000
A27: Ergebnis | G27: =SUBTOTAL(109,Meal1[Kosten '[€']]) -> 1.4555375 | H27: =SUBTOTAL(109,Meal1[Kalorien '[kcal']]) -> 750 | I27: =SUBTOTAL(109,Meal1[Proteine '[g']]) -> 50 | L27: =SUBTOTAL(109,Meal1[Kalorien vorher '[kcal']]) -> 927.9 | M27: =SUBTOTAL(109,Meal1[Proteine vorher '[g']]) -> 50.1 | N27: {=INDEX(Meal1[Massenanpassung],N29)} -> 371.26214 | O27: {=MIN(IF(Meal1[Massenanpassung]<0,"",Meal1[Relative Abweichung]))} -> 0.85631068
F28: Übrige Kalorien/Proteine: | H28: =Input!B4-Meal1[[#Totals],[Kalorien '[kcal']]] -> 2250 | I28: =Input!B5-Meal1[[#Totals],[Proteine '[g']]] -> 150 | M28: P_soll/K_soll | N28: =K4/K3 -> 0.066666667
M29: min rel. Abw. Zeile | N29: =MATCH(Meal1[[#Totals],[Relative Abweichung]],Meal1[Relative Abweichung],0) -> 2
M30: K_ges mit neuer Masse | N30: {=Meal1[[#Totals],[Kalorien vorher '[kcal']]]-INDEX(Meal1[Kalorien vorher '[kcal']],N29)+Meal1[[#Totals],[Massenanpassung]]*INDEX(Meal1[Kaloriendichte '[kcal/g']],N29)} -> 1034.0825
M31: skal. Faktor für Massen | N31: =K3/N30 -> 0.72528061

Sheet Meal 2
A1: Meal 2
A3: Kalorienbedarf [kcal]: | K3: =IF(ISBLANK(B3),'Meal 1'!H28/(Input!B7-1),B3) -> 750
A4: Proteinbedarf [g]: | K4: =IF(ISBLANK(B4),'Meal 1'!I28/(Input!B6-1),B4) -> 50
A5: Zutat [Name aus Tabelle] | B5: Menge [g] | C5: Spalte1 | D5: Berechnete Menge [g] | E5: Gesamtmenge [g] | F5: Skal. Gesamtmenge [g] | G5: Kosten [€] | H5: Kalorien [kcal] | I5: Proteine [g] | J5: Kaloriendichte [kcal/g] | K5: Proteindichte [g/g] | L5: Kalorien vorher [kcal] | M5: Proteine vorher [g] | N5: Massenanpassung | O5: Relative Abweichung
A6: Rinderhackfleisch | B6: 200 | D6: =IF(ROW()-5=$N$29,Meal2[[#Totals],[Massenanpassung]]*$N$31,Meal2[[#This Row],[Menge '[g']]]*$N$31) -> 176.08896 | E6: =Meal2[[#This Row],[Berechnete Menge '[g']]]*Input!$B$7 -> 704.35586 | F6: =IFERROR(Meal2[[#This Row],[Gesamtmenge '[g']]]*$L$36,"-") -> - | G6: =IFERROR(VLOOKUP(Meal2[[#This Row],[Zutat '[Name aus Tabelle']]],Tabelle2[],11,FALSE)*Meal2[[#This Row],[Berechnete Menge '[g']]],"") -> 2.1086653 | H6: =IFERROR(Meal2[[#This Row],[Berechnete Menge '[g']]]*Meal2[[#This Row],[Kaloriendichte '[kcal/g']]],"") -> 413.80907 | I6: =IFERROR(Meal2[[#This Row],[Berechnete Menge '[g']]]*Meal2[[#This Row],[Proteindichte '[g/g']]],"") -> 35.217793 | J6: =IFERROR(VLOOKUP(Meal2[[#This Row],[Zutat '[Name aus Tabelle']]],Tabelle2[],13,FALSE),"") -> 2.35 | K6: =IFERROR(VLOOKUP(Meal2[[#This Row],[Zutat '[Name aus Tabelle']]],Tabelle2[],14,FALSE),"") -> 0.2 | L6: =IFERROR(Meal2[[#This Row],[Kaloriendichte '[kcal/g']]]*Meal2[[#This Row],[Menge '[g']]],0) -> 470 | M6: =IFERROR(Meal2[[#This Row],[Proteindichte '[g/g']]]*Meal2[[#This Row],[Menge '[g']]],0) -> 40 | N6: =IFERROR(($N$28*(Meal2[[#Totals],[Kalorien vorher '[kcal']]]-Meal2[[#This Row],[Kalorien vorher '[kcal']]])-(Meal2[[#Totals],[Proteine vorher '[g']]]-Meal2[[#This Row],[Proteine vorher '[g']]]))/(Meal2[[#This Row],[Proteindichte '[g/g']]]-$N$28*Meal2[[#This Row],[Kaloriendichte '[kcal/g']]]),1000000) -> 169.28462 | O6: =IFERROR(ABS(Meal2[[#This Row],[Massenanpassung]]-Meal2[[#This Row],[Menge '[g']]])/Meal2[[#This Row],[Menge '[g']]],1000000) -> 0.15357692
A7: Grüne Bohnen | B7: 170 | D7: =IF(ROW()-5=$N$29,Meal2[[#Totals],[Massenanpassung]]*$N$31,Meal2[[#This Row],[Menge '[g']]]*$N$31) -> 176.8331 | E7: =Meal2[[#This Row],[Berechnete Menge '[g']]]*Input!$B$7 -> 707.33241 | F7: =IFERROR(Meal2[[#This Row],[Gesamtmenge '[g']]]*$L$36,"-") -> - | G7: =IFERROR(VLOOKUP(Meal2[[#This Row],[Zutat '[Name aus Tabelle']]],Tabelle2[],11,FALSE)*Meal2[[#This Row],[Berechnete Menge '[g']]],"") -> 1.0123695 | H7: =IFERROR(Meal2[[#This Row],[Berechnete Menge '[g']]]*Meal2[[#This Row],[Kaloriendichte '[kcal/g']]],"") -> 54.818262 | I7: =IFERROR(Meal2[[#This Row],[Berechnete Menge '[g']]]*Meal2[[#This Row],[Proteindichte '[g/g']]],"") -> 3.2360458 | J7: =IFERROR(VLOOKUP(Meal2[[#This Row],[Zutat '[Name aus Tabelle']]],Tabelle2[],13,FALSE),"") -> 0.31 | K7: =IFERROR(VLOOKUP(Meal2[[#This Row],[Zutat '[Name aus Tabelle']]],Tabelle2[],14,FALSE),"") -> 0.0183 | L7: =IFERROR(Meal2[[#This Row],[Kaloriendichte '[kcal/g']]]*Meal2[[#This Row],[Menge '[g']]],0) -> 52.7 | M7: =IFERROR(Meal2[[#This Row],[Proteindichte '[g/g']]]*Meal2[[#This Row],[Menge '[g']]],0) -> 3.111 | N7: =IFERROR(($N$28*(Meal2[[#Totals],[Kalorien vorher '[kcal']]]-Meal2[[#This Row],[Kalorien vorher '[kcal']]])-(Meal2[[#Totals],[Proteine vorher '[g']]]-Meal2[[#This Row],[Proteine vorher '[g']]]))/(Meal2[[#This Row],[Proteindichte '[g/g']]]-$N$28*Meal2[[#This Row],[Kaloriendichte '[kcal/g']]]),1000000) -> 732.39437 | O7: =IFERROR(ABS(Meal2[[#This Row],[Massenanpassung]]-Meal2[[#This Row],[Menge '[g']]])/Meal2[[#This Row],[Menge '[g']]],1000000) -> 3.3082022
A8: Kartoffeln | B8: 200 | D8: =IF(ROW()-5=$N$29,Meal2[[#Totals],[Massenanpassung]]*$N$31,Meal2[[#This Row],[Menge '[g']]]*$N$31) -> 208.03894 | E8: =Meal2[[#This Row],[Berechnete Menge '[g']]]*Input!$B$7 -> 832.15578 | F8: =IFERROR(Meal2[[#This Row],[Gesamtmenge '[g']]]*$L$36,"-") -> - | G8: =IFERROR(VLOOKUP(Meal2[[#This Row],[Zutat '[Name aus Tabelle']]],Tabelle2[],11,FALSE)*Meal2[[#This Row],[Berechnete Menge '[g']]],"") -> 0.24860654 | H8: =IFERROR(Meal2[[#This Row],[Berechnete Menge '[g']]]*Meal2[[#This Row],[Kaloriendichte '[kcal/g']]],"") -> 143.54687 | I8: =IFERROR(Meal2[[#This Row],[Berechnete Menge '[g']]]*Meal2[[#This Row],[Proteindichte '[g/g']]],"") -> 4.1607789 | J8: =IFERROR(VLOOKUP(Meal2[[#This Row],[Zutat '[Name aus Tabelle']]],Tabelle2[],13,FALSE),"") -> 0.69 | K8: =IFERROR(VLOOKUP(Meal2[[#This Row],[Zutat '[Name aus Tabelle']]],Tabelle2[],14,FALSE),"") -> 0.02 | L8: =IFERROR(Meal2[[#This Row],[Kaloriendichte '[kcal/g']]]*Meal2[[#This Row],[Menge '[g']]],0) -> 138 | M8: =IFERROR(Meal2[[#This Row],[Proteindichte '[g/g']]]*Meal2[[#This Row],[Menge '[g']]],0) -> 4 | N8: =IFERROR(($N$28*(Meal2[[#Totals],[Kalorien vorher '[kcal']]]-Meal2[[#This Row],[Kalorien vorher '[kcal']]])-(Meal2[[#Totals],[Proteine vorher '[g']]]-Meal2[[#This Row],[Proteine vorher '[g']]]))/(Meal2[[#This Row],[Proteindichte '[g/g']]]-$N$28*Meal2[[#This Row],[Kaloriendichte '[kcal/g']]]),1000000) -> 251.19231 | O8: =IFERROR(ABS(Meal2[[#This Row],[Massenanpassung]]-Meal2[[#This Row],[Menge '[g']]])/Meal2[[#This Row],[Menge '[g']]],1000000) -> 0.25596154
A9: Feta-Käse | B9: 50 | D9: =IF(ROW()-5=$N$29,Meal2[[#Totals],[Massenanpassung]]*$N$31,Meal2[[#This Row],[Menge '[g']]]*$N$31) -> 52.009736 | E9: =Meal2[[#This Row],[Berechnete Menge '[g']]]*Input!$B$7 -> 208.03894 | F9: =IFERROR(Meal2[[#This Row],[Gesamtmenge '[g']]]*$L$36,"-") -> - | G9: =IFERROR(VLOOKUP(Meal2[[#This Row],[Zutat '[Name aus Tabelle']]],Tabelle2[],11,FALSE)*Meal2[[#This Row],[Berechnete Menge '[g']]],"") -> 0.83504521 | H9: =IFERROR(Meal2[[#This Row],[Berechnete Menge '[g']]]*Meal2[[#This Row],[Kaloriendichte '[kcal/g']]],"") -> 137.8258 | I9: =IFERROR(Meal2[[#This Row],[Berechnete Menge '[g']]]*Meal2[[#This Row],[Proteindichte '[g/g']]],"") -> 7.3853825 | J9: =IFERROR(VLOOKUP(Meal2[[#This Row],[Zutat '[Name aus Tabelle']]],Tabelle2[],13,FALSE),"") -> 2.65 | K9: =IFERROR(VLOOKUP(Meal2[[#This Row],[Zutat '[Name aus Tabelle']]],Tabelle2[],14,FALSE),"") -> 0.142 | L9: =IFERROR(Meal2[[#This Row],[Kaloriendichte '[kcal/g']]]*Meal2[[#This Row],[Menge '[g']]],0) -> 132.5 | M9: =IFERROR(Meal2[[#This Row],[Proteindichte '[g/g']]]*Meal2[[#This Row],[Menge '[g']]],0) -> 7.1 | N9: =IFERROR(($N$28*(Meal2[[#Totals],[Kalorien vorher '[kcal']]]-Meal2[[#This Row],[Kalorien vorher '[kcal']]])-(Meal2[[#Totals],[Proteine vorher '[g']]]-Meal2[[#This Row],[Proteine vorher '[g']]]))/(Meal2[[#This Row],[Proteindichte '[g/g']]]-$N$28*Meal2[[#This Row],[Kaloriendichte '[kcal/g']]]),1000000) -> 88.394231 | O9: =IFERROR(ABS(Meal2[[#This Row],[Massenanpassung]]-Meal2[[#This Row],[Menge '[g']]])/Meal2[[#This Row],[Menge '[g']]],1000000) -> 0.76788462
D10: =IF(ROW()-5=$N$29,Meal2[[#Totals],[Massenanpassung]]*$N$31,Meal2[[#This Row],[Menge '[g']]]*$N$31) -> 0 | E10: =Meal2[[#This Row],[Berechnete Menge '[g']]]*Input!$B$7 -> 0 | F10: =IFERROR(Meal2[[#This Row],[Gesamtmenge '[g']]]*$L$36,"-") -> - | G10: =IFERROR(VLOOKUP(Meal2[[#This Row],[Zutat '[Name aus Tabelle']]],Tabelle2[],11,FALSE)*Meal2[[#This Row],[Berechnete Menge '[g']]],"") | H10: =IFERROR(Meal2[[#This Row],[Berechnete Menge '[g']]]*Meal2[[#This Row],[Kaloriendichte '[kcal/g']]],"") | I10: =IFERROR(Meal2[[#This Row],[Berechnete Menge '[g']]]*Meal2[[#This Row],[Proteindichte '[g/g']]],"") | J10: =IFERROR(VLOOKUP(Meal2[[#This Row],[Zutat '[Name aus Tabelle']]],Tabelle2[],13,FALSE),"") | K10: =IFERROR(VLOOKUP(Meal2[[#This Row],[Zutat '[Name aus Tabelle']]],Tabelle2[],14,FALSE),"") | L10: =IFERROR(Meal2[[#This Row],[Kaloriendichte '[kcal/g']]]*Meal2[[#This Row],[Menge '[g']]],0) -> 0 | M10: =IFERROR(Meal2[[#This Row],[Proteindichte '[g/g']]]*Meal2[[#This Row],[Menge '[g']]],0) -> 0 | N10: =IFERROR(($N$28*(Meal2[[#Totals],[Kalorien vorher '[kcal']]]-Meal2[[#This Row],[Kalorien vorher '[kcal']]])-(Meal2[[#Totals],[Proteine vorher '[g']]]-Meal2[[#This Row],[Proteine vorher '[g']]]))/(Meal2[[#This Row],[Proteindichte '[g/g']]]-$N$28*Meal2[[#This Row],[Kaloriendichte '[kcal/g']]]),1000000) -> 1000000 | O10: =IFERROR(ABS(Meal2[[#This Row],[Massenanpassung]]-Meal2[[#This Row],[Menge '[g']]])/Meal2[[#This Row],[Menge '[g']]],1000000) -> 1000000
D11: =IF(ROW()-5=$N$29,Meal2[[#Totals],[Massenanpassung]]*$N$31,Meal2[[#This Row],[Menge '[g']]]*$N$31) -> 0 | E11: =Meal2[[#This Row],[Berechnete Menge '[g']]]*Input!$B$7 -> 0 | F11: =IFERROR(Meal2[[#This Row],[Gesamtmenge '[g']]]*$L$36,"-") -> - | G11: =IFERROR(VLOOKUP(Meal2[[#This Row],[Zutat '[Name aus Tabelle']]],Tabelle2[],11,FALSE)*Meal2[[#This Row],[Berechnete Menge '[g']]],"") | H11: =IFERROR(Meal2[[#This Row],[Berechnete Menge '[g']]]*Meal2[[#This Row],[Kaloriendichte '[kcal/g']]],"") | I11: =IFERROR(Meal2[[#This Row],[Berechnete Menge '[g']]]*Meal2[[#This Row],[Proteindichte '[g/g']]],"") | J11: =IFERROR(VLOOKUP(Meal2[[#This Row],[Zutat '[Name aus Tabelle']]],Tabelle2[],13,FALSE),"") | K11: =IFERROR(VLOOKUP(Meal2[[#This Row],[Zutat '[Name aus Tabelle']]],Tabelle2[],14,FALSE),"") | L11: =IFERROR(Meal2[[#This Row],[Kaloriendichte '[kcal/g']]]*Meal2[[#This Row],[Menge '[g']]],0) -> 0 | M11: =IFERROR(Meal2[[#This Row],[Proteindichte '[g/g']]]*Meal2[[#This Row],[Menge '[g']]],0) -> 0 | N11: =IFERROR(($N$28*(Meal2[[#Totals],[Kalorien vorher '[kcal']]]-Meal2[[#This Row],[Kalorien vorher '[kcal']]])-(Meal2[[#Totals],[Proteine vorher '[g']]]-Meal2[[#This Row],[Proteine vorher '[g']]]))/(Meal2[[#This Row],[Proteindichte '[g/g']]]-$N$28*Meal2[[#This Row],[Kaloriendichte '[kcal/g']]]),1000000) -> 1000000 | O11: =IFERROR(ABS(Meal2[[#This Row],[Massenanpassung]]-Meal2[[#This Row],[Menge '[g']]])/Meal2[[#This Row],[Menge '[g']]],1000000) -> 1000000
D12: =IF(ROW()-5=$N$29,Meal2[[#Totals],[Massenanpassung]]*$N$31,Meal2[[#This Row],[Menge '[g']]]*$N$31) -> 0 | E12: =Meal2[[#This Row],[Berechnete Menge '[g']]]*Input!$B$7 -> 0 | F12: =IFERROR(Meal2[[#This Row],[Gesamtmenge '[g']]]*$L$36,"-") -> - | G12: =IFERROR(VLOOKUP(Meal2[[#This Row],[Zutat '[Name aus Tabelle']]],Tabelle2[],11,FALSE)*Meal2[[#This Row],[Berechnete Menge '[g']]],"") | H12: =IFERROR(Meal2[[#This Row],[Berechnete Menge '[g']]]*Meal2[[#This Row],[Kaloriendichte '[kcal/g']]],"") | I12: =IFERROR(Meal2[[#This Row],[Berechnete Menge '[g']]]*Meal2[[#This Row],[Proteindichte '[g/g']]],"") | J12: =IFERROR(VLOOKUP(Meal2[[#This Row],[Zutat '[Name aus Tabelle']]],Tabelle2[],13,FALSE),"") | K12: =IFERROR(VLOOKUP(Meal2[[#This Row],[Zutat '[Name aus Tabelle']]],Tabelle2[],14,FALSE),"") | L12: =IFERROR(Meal2[[#This Row],[Kaloriendichte '[kcal/g']]]*Meal2[[#This Row],[Menge '[g']]],0) -> 0 | M12: =IFERROR(Meal2[[#This Row],[Proteindichte '[g/g']]]*Meal2[[#This Row],[Menge '[g']]],0) -> 0 | N12: =IFERROR(($N$28*(Meal2[[#Totals],[Kalorien vorher '[kcal']]]-Meal2[[#This Row],[Kalorien vorher '[kcal']]])-(Meal2[[#Totals],[Proteine vorher '[g']]]-Meal2[[#This Row],[Proteine vorher '[g']]]))/(Meal2[[#This Row],[Proteindichte '[g/g']]]-$N$28*Meal2[[#This Row],[Kaloriendichte '[kcal/g']]]),1000000) -> 1000000 | O12: =IFERROR(ABS(Meal2[[#This Row],[Massenanpassung]]-Meal2[[#This Row],[Menge '[g']]])/Meal2[[#This Row],[Menge '[g']]],1000000) -> 1000000
D13: =IF(ROW()-5=$N$29,Meal2[[#Totals],[Massenanpassung]]*$N$31,Meal2[[#This Row],[Menge '[g']]]*$N$31) -> 0 | E13: =Meal2[[#This Row],[Berechnete Menge '[g']]]*Input!$B$7 -> 0 | F13: =IFERROR(Meal2[[#This Row],[Gesamtmenge '[g']]]*$L$36,"-") -> - | G13: =IFERROR(VLOOKUP(Meal2[[#This Row],[Zutat '[Name aus Tabelle']]],Tabelle2[],11,FALSE)*Meal2[[#This Row],[Berechnete Menge '[g']]],"") | H13: =IFERROR(Meal2[[#This Row],[Berechnete Menge '[g']]]*Meal2[[#This Row],[Kaloriendichte '[kcal/g']]],"") | I13: =IFERROR(Meal2[[#This Row],[Berechnete Menge '[g']]]*Meal2[[#This Row],[Proteindichte '[g/g']]],"") | J13: =IFERROR(VLOOKUP(Meal2[[#This Row],[Zutat '[Name aus Tabelle']]],Tabelle2[],13,FALSE),"") | K13: =IFERROR(VLOOKUP(Meal2[[#This Row],[Zutat '[Name aus Tabelle']]],Tabelle2[],14,FALSE),"") | L13: =IFERROR(Meal2[[#This Row],[Kaloriendichte '[kcal/g']]]*Meal2[[#This Row],[Menge '[g']]],0) -> 0 | M13: =IFERROR(Meal2[[#This Row],[Proteindichte '[g/g']]]*Meal2[[#This Row],[Menge '[g']]],0) -> 0 | N13: =IFERROR(($N$28*(Meal2[[#Totals],[Kalorien vorher '[kcal']]]-Meal2[[#This Row],[Kalorien vorher '[kcal']]])-(Meal2[[#Totals],[Proteine vorher '[g']]]-Meal2[[#This Row],[Proteine vorher '[g']]]))/(Meal2[[#This Row],[Proteindichte '[g/g']]]-$N$28*Meal2[[#This Row],[Kaloriendichte '[kcal/g']]]),1000000) -> 1000000 | O13: =IFERROR(ABS(Meal2[[#This Row],[Massenanpassung]]-Meal2[[#This Row],[Menge '[g']]])/Meal2[[#This Row],[Menge '[g']]],1000000) -> 1000000
D14: =IF(ROW()-5=$N$29,Meal2[[#Totals],[Massenanpassung]]*$N$31,Meal2[[#This Row],[Menge '[g']]]*$N$31) -> 0 | E14: =Meal2[[#This Row],[Berechnete Menge '[g']]]*Input!$B$7 -> 0 | F14: =IFERROR(Meal2[[#This Row],[Gesamtmenge '[g']]]*$L$36,"-") -> - | G14: =IFERROR(VLOOKUP(Meal2[[#This Row],[Zutat '[Name aus Tabelle']]],Tabelle2[],11,FALSE)*Meal2[[#This Row],[Berechnete Menge '[g']]],"") | H14: =IFERROR(Meal2[[#This Row],[Berechnete Menge '[g']]]*Meal2[[#This Row],[Kaloriendichte '[kcal/g']]],"") | I14: =IFERROR(Meal2[[#This Row],[Berechnete Menge '[g']]]*Meal2[[#This Row],[Proteindichte '[g/g']]],"") | J14: =IFERROR(VLOOKUP(Meal2[[#This Row],[Zutat '[Name aus Tabelle']]],Tabelle2[],13,FALSE),"") | K14: =IFERROR(VLOOKUP(Meal2[[#This Row],[Zutat '[Name aus Tabelle']]],Tabelle2[],14,FALSE),"") | L14: =IFERROR(Meal2[[#This Row],[Kaloriendichte '[kcal/g']]]*Meal2[[#This Row],[Menge '[g']]],0) -> 0 | M14: =IFERROR(Meal2[[#This Row],[Proteindichte '[g/g']]]*Meal2[[#This Row],[Menge '[g']]],0) -> 0 | N14: =IFERROR(($N$28*(Meal2[[#Totals],[Kalorien vorher '[kcal']]]-Meal2[[#This Row],[Kalorien vorher '[kcal']]])-(Meal2[[#Totals],[Proteine vorher '[g']]]-Meal2[[#This Row],[Proteine vorher '[g']]]))/(Meal2[[#This Row],[Proteindichte '[g/g']]]-$N$28*Meal2[[#This Row],[Kaloriendichte '[kcal/g']]]),1000000) -> 1000000 | O14: =IFERROR(ABS(Meal2[[#This Row],[Massenanpassung]]-Meal2[[#This Row],[Menge '[g']]])/Meal2[[#This Row],[Menge '[g']]],1000000) -> 1000000
D15: =IF(ROW()-5=$N$29,Meal2[[#Totals],[Massenanpassung]]*$N$31,Meal2[[#This Row],[Menge '[g']]]*$N$31) -> 0 | E15: =Meal2[[#This Row],[Berechnete Menge '[g']]]*Input!$B$7 -> 0 | F15: =IFERROR(Meal2[[#This Row],[Gesamtmenge '[g']]]*$L$36,"-") -> - | G15: =IFERROR(VLOOKUP(Meal2[[#This Row],[Zutat '[Name aus Tabelle']]],Tabelle2[],11,FALSE)*Meal2[[#This Row],[Berechnete Menge '[g']]],"") | H15: =IFERROR(Meal2[[#This Row],[Berechnete Menge '[g']]]*Meal2[[#This Row],[Kaloriendichte '[kcal/g']]],"") | I15: =IFERROR(Meal2[[#This Row],[Berechnete Menge '[g']]]*Meal2[[#This Row],[Proteindichte '[g/g']]],"") | J15: =IFERROR(VLOOKUP(Meal2[[#This Row],[Zutat '[Name aus Tabelle']]],Tabelle2[],13,FALSE),"") | K15: =IFERROR(VLOOKUP(Meal2[[#This Row],[Zutat '[Name aus Tabelle']]],Tabelle2[],14,FALSE),"") | L15: =IFERROR(Meal2[[#This Row],[Kaloriendichte '[kcal/g']]]*Meal2[[#This Row],[Menge '[g']]],0) -> 0 | M15: =IFERROR(Meal2[[#This Row],[Proteindichte '[g/g']]]*Meal2[[#This Row],[Menge '[g']]],0) -> 0 | N15: =IFERROR(($N$28*(Meal2[[#Totals],[Kalorien vorher '[kcal']]]-Meal2[[#This Row],[Kalorien vorher '[kcal']]])-(Meal2[[#Totals],[Proteine vorher '[g']]]-Meal2[[#This Row],[Proteine vorher '[g']]]))/(Meal2[[#This Row],[Proteindichte '[g/g']]]-$N$28*Meal2[[#This Row],[Kaloriendichte '[kcal/g']]]),1000000) -> 1000000 | O15: =IFERROR(ABS(Meal2[[#This Row],[Massenanpassung]]-Meal2[[#This Row],[Menge '[g']]])/Meal2[[#This Row],[Menge '[g']]],1000000) -> 1000000
D16: =IF(ROW()-5=$N$29,Meal2[[#Totals],[Massenanpassung]]*$N$31,Meal2[[#This Row],[Menge '[g']]]*$N$31) -> 0 | E16: =Meal2[[#This Row],[Berechnete Menge '[g']]]*Input!$B$7 -> 0 | F16: =IFERROR(Meal2[[#This Row],[Gesamtmenge '[g']]]*$L$36,"-") -> - | G16: =IFERROR(VLOOKUP(Meal2[[#This Row],[Zutat '[Name aus Tabelle']]],Tabelle2[],11,FALSE)*Meal2[[#This Row],[Berechnete Menge '[g']]],"") | H16: =IFERROR(Meal2[[#This Row],[Berechnete Menge '[g']]]*Meal2[[#This Row],[Kaloriendichte '[kcal/g']]],"") | I16: =IFERROR(Meal2[[#This Row],[Berechnete Menge '[g']]]*Meal2[[#This Row],[Proteindichte '[g/g']]],"") | J16: =IFERROR(VLOOKUP(Meal2[[#This Row],[Zutat '[Name aus Tabelle']]],Tabelle2[],13,FALSE),"") | K16: =IFERROR(VLOOKUP(Meal2[[#This Row],[Zutat '[Name aus Tabelle']]],Tabelle2[],14,FALSE),"") | L16: =IFERROR(Meal2[[#This Row],[Kaloriendichte '[kcal/g']]]*Meal2[[#This Row],[Menge '[g']]],0) -> 0 | M16: =IFERROR(Meal2[[#This Row],[Proteindichte '[g/g']]]*Meal2[[#This Row],[Menge '[g']]],0) -> 0 | N16: =IFERROR(($N$28*(Meal2[[#Totals],[Kalorien vorher '[kcal']]]-Meal2[[#This Row],[Kalorien vorher '[kcal']]])-(Meal2[[#Totals],[Proteine vorher '[g']]]-Meal2[[#This Row],[Proteine vorher '[g']]]))/(Meal2[[#This Row],[Proteindichte '[g/g']]]-$N$28*Meal2[[#This Row],[Kaloriendichte '[kcal/g']]]),1000000) -> 1000000 | O16: =IFERROR(ABS(Meal2[[#This Row],[Massenanpassung]]-Meal2[[#This Row],[Menge '[g']]])/Meal2[[#This Row],[Menge '[g']]],1000000) -> 1000000
D17: =IF(ROW()-5=$N$29,Meal2[[#Totals],[Massenanpassung]]*$N$31,Meal2[[#This Row],[Menge '[g']]]*$N$31) -> 0 | E17: =Meal2[[#This Row],[Berechnete Menge '[g']]]*Input!$B$7 -> 0 | F17: =IFERROR(Meal2[[#This Row],[Gesamtmenge '[g']]]*$L$36,"-") -> - | G17: =IFERROR(VLOOKUP(Meal2[[#This Row],[Zutat '[Name aus Tabelle']]],Tabelle2[],11,FALSE)*Meal2[[#This Row],[Berechnete Menge '[g']]],"") | H17: =IFERROR(Meal2[[#This Row],[Berechnete Menge '[g']]]*Meal2[[#This Row],[Kaloriendichte '[kcal/g']]],"") | I17: =IFERROR(Meal2[[#This Row],[Berechnete Menge '[g']]]*Meal2[[#This Row],[Proteindichte '[g/g']]],"") | J17: =IFERROR(VLOOKUP(Meal2[[#This Row],[Zutat '[Name aus Tabelle']]],Tabelle2[],13,FALSE),"") | K17: =IFERROR(VLOOKUP(Meal2[[#This Row],[Zutat '[Name aus Tabelle']]],Tabelle2[],14,FALSE),"") | L17: =IFERROR(Meal2[[#This Row],[Kaloriendichte '[kcal/g']]]*Meal2[[#This Row],[Menge '[g']]],0) -> 0 | M17: =IFERROR(Meal2[[#This Row],[Proteindichte '[g/g']]]*Meal2[[#This Row],[Menge '[g']]],0) -> 0 | N17: =IFERROR(($N$28*(Meal2[[#Totals],[Kalorien vorher '[kcal']]]-Meal2[[#This Row],[Kalorien vorher '[kcal']]])-(Meal2[[#Totals],[Proteine vorher '[g']]]-Meal2[[#This Row],[Proteine vorher '[g']]]))/(Meal2[[#This Row],[Proteindichte '[g/g']]]-$N$28*Meal2[[#This Row],[Kaloriendichte '[kcal/g']]]),1000000) -> 1000000 | O17: =IFERROR(ABS(Meal2[[#This Row],[Massenanpassung]]-Meal2[[#This Row],[Menge '[g']]])/Meal2[[#This Row],[Menge '[g']]],1000000) -> 1000000
D18: =IF(ROW()-5=$N$29,Meal2[[#Totals],[Massenanpassung]]*$N$31,Meal2[[#This Row],[Menge '[g']]]*$N$31) -> 0 | E18: =Meal2[[#This Row],[Berechnete Menge '[g']]]*Input!$B$7 -> 0 | F18: =IFERROR(Meal2[[#This Row],[Gesamtmenge '[g']]]*$L$36,"-") -> - | G18: =IFERROR(VLOOKUP(Meal2[[#This Row],[Zutat '[Name aus Tabelle']]],Tabelle2[],11,FALSE)*Meal2[[#This Row],[Berechnete Menge '[g']]],"") | H18: =IFERROR(Meal2[[#This Row],[Berechnete Menge '[g']]]*Meal2[[#This Row],[Kaloriendichte '[kcal/g']]],"") | I18: =IFERROR(Meal2[[#This Row],[Berechnete Menge '[g']]]*Meal2[[#This Row],[Proteindichte '[g/g']]],"") | J18: =IFERROR(VLOOKUP(Meal2[[#This Row],[Zutat '[Name aus Tabelle']]],Tabelle2[],13,FALSE),"") | K18: =IFERROR(VLOOKUP(Meal2[[#This Row],[Zutat '[Name aus Tabelle']]],Tabelle2[],14,FALSE),"") | L18: =IFERROR(Meal2[[#This Row],[Kaloriendichte '[kcal/g']]]*Meal2[[#This Row],[Menge '[g']]],0) -> 0 | M18: =IFERROR(Meal2[[#This Row],[Proteindichte '[g/g']]]*Meal2[[#This Row],[Menge '[g']]],0) -> 0 | N18: =IFERROR(($N$28*(Meal2[[#Totals],[Kalorien vorher '[kcal']]]-Meal2[[#This Row],[Kalorien vorher '[kcal']]])-(Meal2[[#Totals],[Proteine vorher '[g']]]-Meal2[[#This Row],[Proteine vorher '[g']]]))/(Meal2[[#This Row],[Proteindichte '[g/g']]]-$N$28*Meal2[[#This Row],[Kaloriendichte '[kcal/g']]]),1000000) -> 1000000 | O18: =IFERROR(ABS(Meal2[[#This Row],[Massenanpassung]]-Meal2[[#This Row],[Menge '[g']]])/Meal2[[#This Row],[Menge '[g']]],1000000) -> 1000000
D19: =IF(ROW()-5=$N$29,Meal2[[#Totals],[Massenanpassung]]*$N$31,Meal2[[#This Row],[Menge '[g']]]*$N$31) -> 0 | E19: =Meal2[[#This Row],[Berechnete Menge '[g']]]*Input!$B$7 -> 0 | F19: =IFERROR(Meal2[[#This Row],[Gesamtmenge '[g']]]*$L$36,"-") -> - | G19: =IFERROR(VLOOKUP(Meal2[[#This Row],[Zutat '[Name aus Tabelle']]],Tabelle2[],11,FALSE)*Meal2[[#This Row],[Berechnete Menge '[g']]],"") | H19: =IFERROR(Meal2[[#This Row],[Berechnete Menge '[g']]]*Meal2[[#This Row],[Kaloriendichte '[kcal/g']]],"") | I19: =IFERROR(Meal2[[#This Row],[Berechnete Menge '[g']]]*Meal2[[#This Row],[Proteindichte '[g/g']]],"") | J19: =IFERROR(VLOOKUP(Meal2[[#This Row],[Zutat '[Name aus Tabelle']]],Tabelle2[],13,FALSE),"") | K19: =IFERROR(VLOOKUP(Meal2[[#This Row],[Zutat '[Name aus Tabelle']]],Tabelle2[],14,FALSE),"") | L19: =IFERROR(Meal2[[#This Row],[Kaloriendichte '[kcal/g']]]*Meal2[[#This Row],[Menge '[g']]],0) -> 0 | M19: =IFERROR(Meal2[[#This Row],[Proteindichte '[g/g']]]*Meal2[[#This Row],[Menge '[g']]],0) -> 0 | N19: =IFERROR(($N$28*(Meal2[[#Totals],[Kalorien vorher '[kcal']]]-Meal2[[#This Row],[Kalorien vorher '[kcal']]])-(Meal2[[#Totals],[Proteine vorher '[g']]]-Meal2[[#This Row],[Proteine vorher '[g']]]))/(Meal2[[#This Row],[Proteindichte '[g/g']]]-$N$28*Meal2[[#This Row],[Kaloriendichte '[kcal/g']]]),1000000) -> 1000000 | O19: =IFERROR(ABS(Meal2[[#This Row],[Massenanpassung]]-Meal2[[#This Row],[Menge '[g']]])/Meal2[[#This Row],[Menge '[g']]],1000000) -> 1000000
D20: =IF(ROW()-5=$N$29,Meal2[[#Totals],[Massenanpassung]]*$N$31,Meal2[[#This Row],[Menge '[g']]]*$N$31) -> 0 | E20: =Meal2[[#This Row],[Berechnete Menge '[g']]]*Input!$B$7 -> 0 | F20: =IFERROR(Meal2[[#This Row],[Gesamtmenge '[g']]]*$L$36,"-") -> - | G20: =IFERROR(VLOOKUP(Meal2[[#This Row],[Zutat '[Name aus Tabelle']]],Tabelle2[],11,FALSE)*Meal2[[#This Row],[Berechnete Menge '[g']]],"") | H20: =IFERROR(Meal2[[#This Row],[Berechnete Menge '[g']]]*Meal2[[#This Row],[Kaloriendichte '[kcal/g']]],"") | I20: =IFERROR(Meal2[[#This Row],[Berechnete Menge '[g']]]*Meal2[[#This Row],[Proteindichte '[g/g']]],"") | J20: =IFERROR(VLOOKUP(Meal2[[#This Row],[Zutat '[Name aus Tabelle']]],Tabelle2[],13,FALSE),"") | K20: =IFERROR(VLOOKUP(Meal2[[#This Row],[Zutat '[Name aus Tabelle']]],Tabelle2[],14,FALSE),"") | L20: =IFERROR(Meal2[[#This Row],[Kaloriendichte '[kcal/g']]]*Meal2[[#This Row],[Menge '[g']]],0) -> 0 | M20: =IFERROR(Meal2[[#This Row],[Proteindichte '[g/g']]]*Meal2[[#This Row],[Menge '[g']]],0) -> 0 | N20: =IFERROR(($N$28*(Meal2[[#Totals],[Kalorien vorher '[kcal']]]-Meal2[[#This Row],[Kalorien vorher '[kcal']]])-(Meal2[[#Totals],[Proteine vorher '[g']]]-Meal2[[#This Row],[Proteine vorher '[g']]]))/(Meal2[[#This Row],[Proteindichte '[g/g']]]-$N$28*Meal2[[#This Row],[Kaloriendichte '[kcal/g']]]),1000000) -> 1000000 | O20: =IFERROR(ABS(Meal2[[#This Row],[Massenanpassung]]-Meal2[[#This Row],[Menge '[g']]])/Meal2[[#This Row],[Menge '[g']]],1000000) -> 1000000
D21: =IF(ROW()-5=$N$29,Meal2[[#Totals],[Massenanpassung]]*$N$31,Meal2[[#This Row],[Menge '[g']]]*$N$31) -> 0 | E21: =Meal2[[#This Row],[Berechnete Menge '[g']]]*Input!$B$7 -> 0 | F21: =IFERROR(Meal2[[#This Row],[Gesamtmenge '[g']]]*$L$36,"-") -> - | G21: =IFERROR(VLOOKUP(Meal2[[#This Row],[Zutat '[Name aus Tabelle']]],Tabelle2[],11,FALSE)*Meal2[[#This Row],[Berechnete Menge '[g']]],"") | H21: =IFERROR(Meal2[[#This Row],[Berechnete Menge '[g']]]*Meal2[[#This Row],[Kaloriendichte '[kcal/g']]],"") | I21: =IFERROR(Meal2[[#This Row],[Berechnete Menge '[g']]]*Meal2[[#This Row],[Proteindichte '[g/g']]],"") | J21: =IFERROR(VLOOKUP(Meal2[[#This Row],[Zutat '[Name aus Tabelle']]],Tabelle2[],13,FALSE),"") | K21: =IFERROR(VLOOKUP(Meal2[[#This Row],[Zutat '[Name aus Tabelle']]],Tabelle2[],14,FALSE),"") | L21: =IFERROR(Meal2[[#This Row],[Kaloriendichte '[kcal/g']]]*Meal2[[#This Row],[Menge '[g']]],0) -> 0 | M21: =IFERROR(Meal2[[#This Row],[Proteindichte '[g/g']]]*Meal2[[#This Row],[Menge '[g']]],0) -> 0 | N21: =IFERROR(($N$28*(Meal2[[#Totals],[Kalorien vorher '[kcal']]]-Meal2[[#This Row],[Kalorien vorher '[kcal']]])-(Meal2[[#Totals],[Proteine vorher '[g']]]-Meal2[[#This Row],[Proteine vorher '[g']]]))/(Meal2[[#This Row],[Proteindichte '[g/g']]]-$N$28*Meal2[[#This Row],[Kaloriendichte '[kcal/g']]]),1000000) -> 1000000 | O21: =IFERROR(ABS(Meal2[[#This Row],[Massenanpassung]]-Meal2[[#This Row],[Menge '[g']]])/Meal2[[#This Row],[Menge '[g']]],1000000) -> 1000000
... D26: =IF(ROW()-5=$N$29,Meal2[[#Totals],[Massenanpassung]]*$N$31,Meal2[[#This Row],[Menge '[g']]]*$N$31) -> 0 | E26: =Meal2[[#This Row],[Berechnete Menge '[g']]]*Input!$B$7 -> 0 | F26: =IFERROR(Meal2[[#This Row],[Gesamtmenge '[g']]]*$L$36,"-") -> - | G26: =IFERROR(VLOOKUP(Meal2[[#This Row],[Zutat '[Name aus Tabelle']]],Tabelle2[],11,FALSE)*Meal2[[#This Row],[Berechnete Menge '[g']]],"") | H26: =IFERROR(Meal2[[#This Row],[Berechnete Menge '[g']]]*Meal2[[#This Row],[Kaloriendichte '[kcal/g']]],"") | I26: =IFERROR(Meal2[[#This Row],[Berechnete Menge '[g']]]*Meal2[[#This Row],[Proteindichte '[g/g']]],"") | J26: =IFERROR(VLOOKUP(Meal2[[#This Row],[Zutat '[Name aus Tabelle']]],Tabelle2[],13,FALSE),"") | K26: =IFERROR(VLOOKUP(Meal2[[#This Row],[Zutat '[Name aus Tabelle']]],Tabelle2[],14,FALSE),"") | L26: =IFERROR(Meal2[[#This Row],[Kaloriendichte '[kcal/g']]]*Meal2[[#This Row],[Menge '[g']]],0) -> 0 | M26: =IFERROR(Meal2[[#This Row],[Proteindichte '[g/g']]]*Meal2[[#This Row],[Menge '[g']]],0) -> 0 | N26: =IFERROR(($N$28*(Meal2[[#Totals],[Kalorien vorher '[kcal']]]-Meal2[[#This Row],[Kalorien vorher '[kcal']]])-(Meal2[[#Totals],[Proteine vorher '[g']]]-Meal2[[#This Row],[Proteine vorher '[g']]]))/(Meal2[[#This Row],[Proteindichte '[g/g']]]-$N$28*Meal2[[#This Row],[Kaloriendichte '[kcal/g']]]),1000000) -> 1000000 | O26: =IFERROR(ABS(Meal2[[#This Row],[Massenanpassung]]-Meal2[[#This Row],[Menge '[g']]])/Meal2[[#This Row],[Menge '[g']]],1000000) -> 1000000
A27: Ergebnis | G27: =SUBTOTAL(109,Meal2[Kosten '[€']]) -> 4.2046866 | H27: =SUBTOTAL(109,Meal2[Kalorien '[kcal']]) -> 750 | I27: =SUBTOTAL(109,Meal2[Proteine '[g']]) -> 50 | L27: =SUBTOTAL(109,Meal2[Kalorien vorher '[kcal']]) -> 793.2 | M27: =SUBTOTAL(109,Meal2[Proteine vorher '[g']]) -> 54.211 | N27: {=INDEX(Meal2[Massenanpassung],N29)} -> 169.28462 | O27: {=MIN(IF(Meal2[Massenanpassung]<0,"",Meal2[Relative Abweichung]))} -> 0.15357692
A28: Übrige Kalorien/Proteine: | H28: ='Meal 1'!H28-Meal2[[#Totals],[Kalorien '[kcal']]] -> 1500 | I28: ='Meal 1'!I28-Meal2[[#Totals],[Proteine '[g']]] -> 100 | M28: P_soll/K_soll | N28: =K4/K3 -> 0.066666667
M29: min rel. Abw. Zeile | N29: =MATCH(Meal2[[#Totals],[Relative Abweichung]],Meal2[Relative Abweichung],0) -> 1
M30: K_ges mit neuer Masse | N30: {=Meal2[[#Totals],[Kalorien vorher '[kcal']]]-INDEX(Meal2[Kalorien vorher '[kcal']],N29)+Meal2[[#Totals],[Massenanpassung]]*INDEX(Meal2[Kaloriendichte '[kcal/g']],N29)} -> 721.01885
M31: skal. Faktor für Massen | N31: =K3/N30 -> 1.0401947
L32: =MATCH(MAX(#REF!),#REF!,0) -> #REF!
L33: =MAX(#REF!) -> #REF!
L34: {=INDEX(#REF!,L32)} -> #REF!
L35: {=INDEX(#REF!,L32)} -> #REF!
L36: =L33*L34/L35 -> #REF!

Sheet Meal 3
A1: Meal 3
A3: Kalorienbedarf [kcal]: | K3: =IF(ISBLANK(B3),'Meal 2'!H28/(Input!B6-2),B3) -> 750
A4: Proteinbedarf [g]: | K4: =IF(ISBLANK(B4),'Meal 2'!I28/(Input!B6-2),B4) -> 50
A5: Zutat [Name aus Tabelle] | B5: Menge [g] | C5: Spalte1 | D5: Berechnete Menge [g] | E5: Gesamtmenge [g] | F5: Skal. Gesamtmenge [g] | G5: Kosten [€] | H5: Kalorien [kcal] | I5: Proteine [g] | J5: Kaloriendichte [kcal/g] | K5: Proteindichte [g/g] | L5: Kalorien vorher [kcal] | M5: Proteine vorher [g] | N5: Massenanpassung | O5: Relative Abweichung
A6: Hähnchenbrustfilet | B6: 525 | D6: =IF(ROW()-5=$N$29,Meal3[[#Totals],[Massenanpassung]]*$N$31,Meal3[[#This Row],[Menge '[g']]]*$N$31) -> 174.6008 | E6: =Meal3[[#This Row],[Berechnete Menge '[g']]]*Input!$B$7 -> 698.40319 | F6: =IFERROR(Meal3[[#This Row],[Gesamtmenge '[g']]]*$L$36,"-") -> 0 | G6: =IFERROR(VLOOKUP(Meal3[[#This Row],[Zutat '[Name aus Tabelle']]],Tabelle2[],11,FALSE)*Meal3[[#This Row],[Berechnete Menge '[g']]],"") -> 2.4394226 | H6: =IFERROR(Meal3[[#This Row],[Berechnete Menge '[g']]]*Meal3[[#This Row],[Kaloriendichte '[kcal/g']]],"") -> 169.36277 | I6: =IFERROR(Meal3[[#This Row],[Berechnete Menge '[g']]]*Meal3[[#This Row],[Proteindichte '[g/g']]],"") -> 34.920159 | J6: =IFERROR(VLOOKUP(Meal3[[#This Row],[Zutat '[Name aus Tabelle']]],Tabelle2[],13,FALSE),"") -> 0.97 | K6: =IFERROR(VLOOKUP(Meal3[[#This Row],[Zutat '[Name aus Tabelle']]],Tabelle2[],14,FALSE),"") -> 0.2 | L6: =IFERROR(Meal3[[#This Row],[Kaloriendichte '[kcal/g']]]*Meal3[[#This Row],[Menge '[g']]],0) -> 509.25 | M6: =IFERROR(Meal3[[#This Row],[Proteindichte '[g/g']]]*Meal3[[#This Row],[Menge '[g']]],0) -> 105 | N6: =IFERROR(($N$28*(Meal3[[#Totals],[Kalorien vorher '[kcal']]]-Meal3[[#This Row],[Kalorien vorher '[kcal']]])-(Meal3[[#Totals],[Proteine vorher '[g']]]-Meal3[[#This Row],[Proteine vorher '[g']]]))/(Meal3[[#This Row],[Proteindichte '[g/g']]]-$N$28*Meal3[[#This Row],[Kaloriendichte '[kcal/g']]]),1000000) -> 551.133 | O6: =IFERROR(ABS(Meal3[[#This Row],[Massenanpassung]]-Meal3[[#This Row],[Menge '[g']]])/Meal3[[#This Row],[Menge '[g']]],1000000) -> 0.049777152
